2024-07-07 15:17:56,280 INFO    StreamThr :64040 [internal.py:wandb_internal():88] W&B internal server running at pid: 64040, started at: 2024-07-07 15:17:56.279890
2024-07-07 15:17:56,282 DEBUG   HandlerThread:64040 [handler.py:handle_request():158] handle_request: status
2024-07-07 15:17:56,289 INFO    WriterThread:64040 [datastore.py:open_for_write():87] open: C:\Users\a0975\fl\wandb\run-20240707_151756-r6g5fn3i\run-r6g5fn3i.wandb
2024-07-07 15:17:56,290 DEBUG   SenderThread:64040 [sender.py:send():379] send: header
2024-07-07 15:17:56,290 DEBUG   SenderThread:64040 [sender.py:send():379] send: run
2024-07-07 15:17:56,669 ERROR   SenderThread:64040 [internal_api.py:execute():349] 404 response executing GraphQL.
2024-07-07 15:17:56,669 ERROR   SenderThread:64040 [internal_api.py:execute():350] {"errors":[{"message":"entity your-entity-name not found during upsertBucket","path":["upsertBucket"]}],"data":{"upsertBucket":null}}
2024-07-07 15:17:56,673 ERROR   SenderThread:64040 [sender.py:send_run():1009] It appears that you do not have permission to access the requested resource. Please reach out to the project owner to grant you access. If you have the correct permissions, verify that there are no issues with your networking setup.(Error 404: Not Found)
Traceback (most recent call last):
  File "C:\Users\a0975\anaconda3\envs\fltest\lib\site-packages\wandb\sdk\lib\retry.py", line 131, in __call__
    result = self._call_fn(*args, **kwargs)
  File "C:\Users\a0975\anaconda3\envs\fltest\lib\site-packages\wandb\sdk\internal\internal_api.py", line 345, in execute
    return self.client.execute(*args, **kwargs)  # type: ignore
  File "C:\Users\a0975\anaconda3\envs\fltest\lib\site-packages\wandb\vendor\gql-0.2.0\wandb_gql\client.py", line 52, in execute
    result = self._get_result(document, *args, **kwargs)
  File "C:\Users\a0975\anaconda3\envs\fltest\lib\site-packages\wandb\vendor\gql-0.2.0\wandb_gql\client.py", line 60, in _get_result
    return self.transport.execute(document, *args, **kwargs)
  File "C:\Users\a0975\anaconda3\envs\fltest\lib\site-packages\wandb\sdk\lib\gql_request.py", line 59, in execute
    request.raise_for_status()
  File "C:\Users\a0975\anaconda3\envs\fltest\lib\site-packages\requests\models.py", line 1021, in raise_for_status
    raise HTTPError(http_error_msg, response=self)
requests.exceptions.HTTPError: 404 Client Error: Not Found for url: https://api.wandb.ai/graphql

During handling of the above exception, another exception occurred:

Traceback (most recent call last):
  File "C:\Users\a0975\anaconda3\envs\fltest\lib\site-packages\wandb\sdk\internal\sender.py", line 1007, in send_run
    server_run = self._init_run(run, config_value_dict)
  File "C:\Users\a0975\anaconda3\envs\fltest\lib\site-packages\wandb\sdk\internal\sender.py", line 1093, in _init_run
    commit=run.git.commit or None,
  File "C:\Users\a0975\anaconda3\envs\fltest\lib\site-packages\wandb\apis\normalize.py", line 73, in wrapper
    raise err
  File "C:\Users\a0975\anaconda3\envs\fltest\lib\site-packages\wandb\apis\normalize.py", line 41, in wrapper
    return func(*args, **kwargs)
  File "C:\Users\a0975\anaconda3\envs\fltest\lib\site-packages\wandb\sdk\internal\internal_api.py", line 2228, in upsert_run
    **kwargs,
  File "C:\Users\a0975\anaconda3\envs\fltest\lib\site-packages\wandb\sdk\internal\internal_api.py", line 320, in gql
    **kwargs,
  File "C:\Users\a0975\anaconda3\envs\fltest\lib\site-packages\wandb\sdk\lib\retry.py", line 147, in __call__
    retry_timedelta_triggered = check_retry_fn(e)
  File "C:\Users\a0975\anaconda3\envs\fltest\lib\site-packages\wandb\util.py", line 968, in check_retry_fn
    return fallback_retry_fn(e)
  File "C:\Users\a0975\anaconda3\envs\fltest\lib\site-packages\wandb\util.py", line 911, in no_retry_auth
    "It appears that you do not have permission to access the requested resource. "
wandb.errors.CommError: It appears that you do not have permission to access the requested resource. Please reach out to the project owner to grant you access. If you have the correct permissions, verify that there are no issues with your networking setup.(Error 404: Not Found)
2024-07-07 15:17:56,753 DEBUG   HandlerThread:64040 [handler.py:handle_request():158] handle_request: shutdown
2024-07-07 15:17:56,753 INFO    HandlerThread:64040 [handler.py:finish():882] shutting down handler
2024-07-07 15:17:57,300 INFO    WriterThread:64040 [datastore.py:close():296] close: C:\Users\a0975\fl\wandb\run-20240707_151756-r6g5fn3i\run-r6g5fn3i.wandb
2024-07-07 15:17:57,686 INFO    SenderThread:64040 [sender.py:finish():1608] shutting down sender
